Workbook

Sheet Parametri_mappa
A1: Mappa valutazioni CBM (accuracy in mezzi punti + 7 livelli CBM attorno alla spezzata)
A3: Parametri algoritmo (come da guida) | D3: Taglio 7 livelli CBM (vicino alla spezzata)
A4: Bmax (bonus max, in decimi) | B4: 3 | D4: f1 (livello vicino) | E4: 0.15
A5: Mmin (malus minimo, in decimi) | B5: -0.5 | D5: f2 (livello più distante) | E5: 0.3
A6: Mmax (malus massimo, in decimi) | B6: -2
D7: Scala distanza (nearest point)
A8: Note | D8: scala voto accuracy (unità = 0,5) | E8: 0.5
D9: scala CBM% (unità = 20) | E9: 20
A10: • La mappa usa Accuracy in decimi (1,0 – 10,0 a passi di 0,5) e calcola 7 punti CBM% per riga: y_low, due sotto y_min, y_min, due sopra y_min, y_max.

Sheet Data_mappa
A1: ID | B1: V_acc (0-10) | C1: Accuracy% | D1: y_min | E1: y_max | F1: y_low | G1: Livello | H1: CBM% (punto mappa) | I1: Adj (decimi) | J1: Voto finale | K1: Profilo | L1: Feedback (breve) | M1: Feedback (esteso) | N1: Key (V_acc|Livello) | O1: Key | P1: Voto_finale | Q1: Profilo | R1: Feedback_breve | S1: Feedback_esteso
A2: 1 | B2: 1 | C2: 10 | D2: 10 | E2: 30 | F2: -50 | G2: Molto sotto (y_low) | H2: -50 | I2: 0 | J2: 1 | K2: Rischio misconcezioni / confidenza fuori bersaglio | L2: Rischio misconcezioni / confidenza fuori bersaglio — Scegli 3 risposte sbagliate e riscrivile con regola/criterio: se non trovi la regola, la prossima volta confidenza bassa. | M2: Le basi sono ancora in costruzione: prima di tutto consolidiamo i concetti. Probabile mix di errori convinti e/o uso non coerente della confidenza: qui si nascondono misconcezioni. Consiglio pratico: Scegli 3 risposte sbagliate e riscrivile con regola/criterio: se non trovi la regola, la prossima volta confidenza bassa. | N2: 1.0|Molto sotto (y_low) | O2: 1.0|Molto sotto (y_low) | P2: 1 | Q2: Rischio misconcezioni / confidenza fuori bersaglio | R2: Rischio misconcezioni / confidenza fuori bersaglio — Scegli 3 risposte sbagliate e riscrivile con regola/criterio: se non trovi la regola, la prossima volta confidenza bassa. | S2: Le basi sono ancora in costruzione: prima di tutto consolidiamo i concetti. Probabile mix di errori convinti e/o uso non coerente della confidenza: qui si nascondono misconcezioni. Consiglio pratico: Scegli 3 risposte sbagliate e riscrivile con regola/criterio: se non trovi la regola, la prossima volta confidenza bassa.
A3: 2 | B3: 1 | C3: 10 | D3: 10 | E3: 30 | F3: -50 | G3: Sotto 2 | H3: -8 | I3: 0 | J3: 1 | K3: Inconsapevolezza marcata (calibrazione scarsa) | L3: Inconsapevolezza marcata (calibrazione scarsa) — Per ogni domanda: scrivi 1 riga di motivazione. Se non la sai scrivere, confidenza bassa senza vergogna. | M3: Le basi sono ancora in costruzione: prima di tutto consolidiamo i concetti. Le risposte corrette non sono ancora distinguibili da quelle incerte: serve allenare il 'so / non so'. Consiglio pratico: Per ogni domanda: scrivi 1 riga di motivazione. Se non la sai scrivere, confidenza bassa senza vergogna. | N3: 1.0|Sotto 2 | O3: 1.0|Sotto 2 | P3: 1 | Q3: Inconsapevolezza marcata (calibrazione scarsa) | R3: Inconsapevolezza marcata (calibrazione scarsa) — Per ogni domanda: scrivi 1 riga di motivazione. Se non la sai scrivere, confidenza bassa senza vergogna. | S3: Le basi sono ancora in costruzione: prima di tutto consolidiamo i concetti. Le risposte corrette non sono ancora distinguibili da quelle incerte: serve allenare il 'so / non so'. Consiglio pratico: Per ogni domanda: scrivi 1 riga di motivazione. Se non la sai scrivere, confidenza bassa senza vergogna.
A4: 3 | B4: 1 | C4: 10 | D4: 10 | E4: 30 | F4: -50 | G4: Sotto 1 | H4: 1 | I4: 0 | J4: 1 | K4: Incertezza / calibrazione da migliorare | L4: Incertezza / calibrazione da migliorare — Allenati con un controllo: 'posso spiegare in 10 secondi perché?' Se sì alza, se no abbassa la confidenza. | M4: Le basi sono ancora in costruzione: prima di tutto consolidiamo i concetti. Sei vicino alla calibrazione, ma c'è ancora rumore: a volte ti fidi troppo o troppo poco. Consiglio pratico: Allenati con un controllo: 'posso spiegare in 10 secondi perché?' Se sì alza, se no abbassa la confidenza. | N4: 1.0|Sotto 1 | O4: 1.0|Sotto 1 | P4: 1 | Q4: Incertezza / calibrazione da migliorare | R4: Incertezza / calibrazione da migliorare — Allenati con un controllo: 'posso spiegare in 10 secondi perché?' Se sì alza, se no abbassa la confidenza. | S4: Le basi sono ancora in costruzione: prima di tutto consolidiamo i concetti. Sei vicino alla calibrazione, ma c'è ancora rumore: a volte ti fidi troppo o troppo poco. Consiglio pratico: Allenati con un controllo: 'posso spiegare in 10 secondi perché?' Se sì alza, se no abbassa la confidenza.
A5: 4 | B5: 1 | C5: 10 | D5: 10 | E5: 30 | F5: -50 | G5: Sulla spezzata (y_min) | H5: 10 | I5: 0 | J5: 1 | K5: Calibrazione minima OK | L5: Calibrazione minima OK — Obiettivo: aumentare la precisione delle motivazioni (non solo la risposta) per salire di livello. | M5: Le basi sono ancora in costruzione: prima di tutto consolidiamo i concetti. Sei sul livello minimo di coerenza: la confidenza è generalmente ragionevole. Consiglio pratico: Obiettivo: aumentare la precisione delle motivazioni (non solo la risposta) per salire di livello. | N5: 1.0|Sulla spezzata (y_min) | O5: 1.0|Sulla spezzata (y_min) | P5: 1 | Q5: Calibrazione minima OK | R5: Calibrazione minima OK — Obiettivo: aumentare la precisione delle motivazioni (non solo la risposta) per salire di livello. | S5: Le basi sono ancora in costruzione: prima di tutto consolidiamo i concetti. Sei sul livello minimo di coerenza: la confidenza è generalmente ragionevole. Consiglio pratico: Obiettivo: aumentare la precisione delle motivazioni (non solo la risposta) per salire di livello.
A6: 5 | B6: 1 | C6: 10 | D6: 10 | E6: 30 | F6: -50 | G6: Sopra 1 | H6: 13 | I6: 0 | J6: 1 | K6: Buona calibrazione (sa e lo sa) | L6: Buona calibrazione (sa e lo sa) — Consolida: rivedi 2 errori e scrivi la 'regola d'oro' che li evita. | M6: Le basi sono ancora in costruzione: prima di tutto consolidiamo i concetti. Buona corrispondenza tra ciò che sai e quanto ti fidi: la tua consapevolezza aiuta a studiare meglio. Consiglio pratico: Consolida: rivedi 2 errori e scrivi la 'regola d'oro' che li evita. | N6: 1.0|Sopra 1 | O6: 1.0|Sopra 1 | P6: 1 | Q6: Buona calibrazione (sa e lo sa) | R6: Buona calibrazione (sa e lo sa) — Consolida: rivedi 2 errori e scrivi la 'regola d'oro' che li evita. | S6: Le basi sono ancora in costruzione: prima di tutto consolidiamo i concetti. Buona corrispondenza tra ciò che sai e quanto ti fidi: la tua consapevolezza aiuta a studiare meglio. Consiglio pratico: Consolida: rivedi 2 errori e scrivi la 'regola d'oro' che li evita.
A7: 6 | B7: 1 | C7: 10 | D7: 10 | E7: 30 | F7: -50 | G7: Sopra 2 | H7: 16 | I7: 0 | J7: 1 | K7: Consapevolezza alta (molto ben tarato) | L7: Consapevolezza alta (molto ben tarato) — Fai un passo in più: spiega a un compagno il criterio (insegnare = super test). | M7: Le basi sono ancora in costruzione: prima di tutto consolidiamo i concetti. Ottima taratura: quando sei sicuro, di solito sei anche corretto. Consiglio pratico: Fai un passo in più: spiega a un compagno il criterio (insegnare = super test). | N7: 1.0|Sopra 2 | O7: 1.0|Sopra 2 | P7: 1 | Q7: Consapevolezza alta (molto ben tarato) | R7: Consapevolezza alta (molto ben tarato) — Fai un passo in più: spiega a un compagno il criterio (insegnare = super test). | S7: Le basi sono ancora in costruzione: prima di tutto consolidiamo i concetti. Ottima taratura: quando sei sicuro, di solito sei anche corretto. Consiglio pratico: Fai un passo in più: spiega a un compagno il criterio (insegnare = super test).
A8: 7 | B8: 1 | C8: 10 | D8: 10 | E8: 30 | F8: -50 | G8: Retta consapevolezza (y_max) | H8: 30 | I8: 0 | J8: 1 | K8: Consapevolezza eccellente | L8: Consapevolezza eccellente — Sfida extra: prova a individuare i casi limite e le eccezioni (rafforza il pensiero critico). | M8: Le basi sono ancora in costruzione: prima di tutto consolidiamo i concetti. Prestazione e consapevolezza vanno insieme: sei molto affidabile nelle tue scelte. Consiglio pratico: Sfida extra: prova a individuare i casi limite e le eccezioni (rafforza il pensiero critico). | N8: 1.0|Retta consapevolezza (y_max) | O8: 1.0|Retta consapevolezza (y_max) | P8: 1 | Q8: Consapevolezza eccellente | R8: Consapevolezza eccellente — Sfida extra: prova a individuare i casi limite e le eccezioni (rafforza il pensiero critico). | S8: Le basi sono ancora in costruzione: prima di tutto consolidiamo i concetti. Prestazione e consapevolezza vanno insieme: sei molto affidabile nelle tue scelte. Consiglio pratico: Sfida extra: prova a individuare i casi limite e le eccezioni (rafforza il pensiero critico).
A9: 8 | B9: 1.5 | C9: 15 | D9: 15 | E9: 45 | F9: -45 | G9: Molto sotto (y_low) | H9: -45 | I9: 0 | J9: 1.5 | K9: Rischio misconcezioni / confidenza fuori bersaglio | L9: Rischio misconcezioni / confidenza fuori bersaglio — Scegli 3 risposte sbagliate e riscrivile con regola/criterio: se non trovi la regola, la prossima volta confidenza bassa. | M9: Le basi sono ancora in costruzione: prima di tutto consolidiamo i concetti. Probabile mix di errori convinti e/o uso non coerente della confidenza: qui si nascondono misconcezioni. Consiglio pratico: Scegli 3 risposte sbagliate e riscrivile con regola/criterio: se non trovi la regola, la prossima volta confidenza bassa. | N9: 1.5|Molto sotto (y_low) | O9: 1.5|Molto sotto (y_low) | P9: 1.5 | Q9: Rischio misconcezioni / confidenza fuori bersaglio | R9: Rischio misconcezioni / confidenza fuori bersaglio — Scegli 3 risposte sbagliate e riscrivile con regola/criterio: se non trovi la regola, la prossima volta confidenza bassa. | S9: Le basi sono ancora in costruzione: prima di tutto consolidiamo i concetti. Probabile mix di errori convinti e/o uso non coerente della confidenza: qui si nascondono misconcezioni. Consiglio pratico: Scegli 3 risposte sbagliate e riscrivile con regola/criterio: se non trovi la regola, la prossima volta confidenza bassa.
A10: 9 | B10: 1.5 | C10: 15 | D10: 15 | E10: 45 | F10: -45 | G10: Sotto 2 | H10: -3 | I10: 0 | J10: 1.5 | K10: Inconsapevolezza marcata (calibrazione scarsa) | L10: Inconsapevolezza marcata (calibrazione scarsa) — Per ogni domanda: scrivi 1 riga di motivazione. Se non la sai scrivere, confidenza bassa senza vergogna. | M10: Le basi sono ancora in costruzione: prima di tutto consolidiamo i concetti. Le risposte corrette non sono ancora distinguibili da quelle incerte: serve allenare il 'so / non so'. Consiglio pratico: Per ogni domanda: scrivi 1 riga di motivazione. Se non la sai scrivere, confidenza bassa senza vergogna. | N10: 1.5|Sotto 2 | O10: 1.5|Sotto 2 | P10: 1.5 | Q10: Inconsapevolezza marcata (calibrazione scarsa) | R10: Inconsapevolezza marcata (calibrazione scarsa) — Per ogni domanda: scrivi 1 riga di motivazione. Se non la sai scrivere, confidenza bassa senza vergogna. | S10: Le basi sono ancora in costruzione: prima di tutto consolidiamo i concetti. Le risposte corrette non sono ancora distinguibili da quelle incerte: serve allenare il 'so / non so'. Consiglio pratico: Per ogni domanda: scrivi 1 riga di motivazione. Se non la sai scrivere, confidenza bassa senza vergogna.
A11: 10 | B11: 1.5 | C11: 15 | D11: 15 | E11: 45 | F11: -45 | G11: Sotto 1 | H11: 6 | I11: 0 | J11: 1.5 | K11: Incertezza / calibrazione da migliorare | L11: Incertezza / calibrazione da migliorare — Allenati con un controllo: 'posso spiegare in 10 secondi perché?' Se sì alza, se no abbassa la confidenza. | M11: Le basi sono ancora in costruzione: prima di tutto consolidiamo i concetti. Sei vicino alla calibrazione, ma c'è ancora rumore: a volte ti fidi troppo o troppo poco. Consiglio pratico: Allenati con un controllo: 'posso spiegare in 10 secondi perché?' Se sì alza, se no abbassa la confidenza. | N11: 1.5|Sotto 1 | O11: 1.5|Sotto 1 | P11: 1.5 | Q11: Incertezza / calibrazione da migliorare | R11: Incertezza / calibrazione da migliorare — Allenati con un controllo: 'posso spiegare in 10 secondi perché?' Se sì alza, se no abbassa la confidenza. | S11: Le basi sono ancora in costruzione: prima di tutto consolidiamo i concetti. Sei vicino alla calibrazione, ma c'è ancora rumore: a volte ti fidi troppo o troppo poco. Consiglio pratico: Allenati con un controllo: 'posso spiegare in 10 secondi perché?' Se sì alza, se no abbassa la confidenza.
A12: 11 | B12: 1.5 | C12: 15 | D12: 15 | E12: 45 | F12: -45 | G12: Sulla spezzata (y_min) | H12: 15 | I12: 0 | J12: 1.5 | K12: Calibrazione minima OK | L12: Calibrazione minima OK — Obiettivo: aumentare la precisione delle motivazioni (non solo la risposta) per salire di livello. | M12: Le basi sono ancora in costruzione: prima di tutto consolidiamo i concetti. Sei sul livello minimo di coerenza: la confidenza è generalmente ragionevole. Consiglio pratico: Obiettivo: aumentare la precisione delle motivazioni (non solo la risposta) per salire di livello. | N12: 1.5|Sulla spezzata (y_min) | O12: 1.5|Sulla spezzata (y_min) | P12: 1.5 | Q12: Calibrazione minima OK | R12: Calibrazione minima OK — Obiettivo: aumentare la precisione delle motivazioni (non solo la risposta) per salire di livello. | S12: Le basi sono ancora in costruzione: prima di tutto consolidiamo i concetti. Sei sul livello minimo di coerenza: la confidenza è generalmente ragionevole. Consiglio pratico: Obiettivo: aumentare la precisione delle motivazioni (non solo la risposta) per salire di livello.
A13: 12 | B13: 1.5 | C13: 15 | D13: 15 | E13: 45 | F13: -45 | G13: Sopra 1 | H13: 19.5 | I13: 0 | J13: 1.5 | K13: Buona calibrazione (sa e lo sa) | L13: Buona calibrazione (sa e lo sa) — Consolida: rivedi 2 errori e scrivi la 'regola d'oro' che li evita. | M13: Le basi sono ancora in costruzione: prima di tutto consolidiamo i concetti. Buona corrispondenza tra ciò che sai e quanto ti fidi: la tua consapevolezza aiuta a studiare meglio. Consiglio pratico: Consolida: rivedi 2 errori e scrivi la 'regola d'oro' che li evita. | N13: 1.5|Sopra 1 | O13: 1.5|Sopra 1 | P13: 1.5 | Q13: Buona calibrazione (sa e lo sa) | R13: Buona calibrazione (sa e lo sa) — Consolida: rivedi 2 errori e scrivi la 'regola d'oro' che li evita. | S13: Le basi sono ancora in costruzione: prima di tutto consolidiamo i concetti. Buona corrispondenza tra ciò che sai e quanto ti fidi: la tua consapevolezza aiuta a studiare meglio. Consiglio pratico: Consolida: rivedi 2 errori e scrivi la 'regola d'oro' che li evita.
... A134: 133 | B134: 10 | C134: 100 | D134: 300 | E134: 300 | F134: 40 | G134: Retta consapevolezza (y_max) | H134: 300 | I134: 0 | J134: 10 | K134: Consapevolezza eccellente | L134: Consapevolezza eccellente — Sfida extra: prova a individuare i casi limite e le eccezioni (rafforza il pensiero critico). | M134: Competenza molto alta: puntiamo alla solidità e ai casi limite. Prestazione e consapevolezza vanno insieme: sei molto affidabile nelle tue scelte. Consiglio pratico: Sfida extra: prova a individuare i casi limite e le eccezioni (rafforza il pensiero critico). | N134: 10.0|Retta consapevolezza (y_max) | O134: 10.0|Retta consapevolezza (y_max) | P134: 10 | Q134: Consapevolezza eccellente | R134: Consapevolezza eccellente — Sfida extra: prova a individuare i casi limite e le eccezioni (rafforza il pensiero critico). | S134: Competenza molto alta: puntiamo alla solidità e ai casi limite. Prestazione e consapevolezza vanno insieme: sei molto affidabile nelle tue scelte. Consiglio pratico: Sfida extra: prova a individuare i casi limite e le eccezioni (rafforza il pensiero critico).

Sheet Mappa_0p5
A1: Mappa Accuracy (0–10, step 0,5) × 7 livelli CBM% (attorno alla spezzata)
A3: Voto accuracy | B3: Accuracy% | C3: Molto sotto (y_low) | D3: Sotto 2 | E3: Sotto 1 | F3: Sulla spezzata (y_min) | G3: Sopra 1 | H3: Sopra 2 | I3: Retta consapevolezza (y_max)
A4: 1 | B4: 10 | C4: CBM≈-50% Vf≈1.00 Rischio misconcezioni / confidenza fuori bersaglio Scegli 3 risposte sbagliate e riscrivile con regola/criterio: se non trovi la regola, la prossima volta confidenza bassa. | D4: CBM≈-8% Vf≈1.00 Inconsapevolezza marcata (calibrazione scarsa) Per ogni domanda: scrivi 1 riga di motivazione. Se non la sai scrivere, confidenza bassa senza vergogna. | E4: CBM≈1% Vf≈1.00 Incertezza / calibrazione da migliorare Allenati con un controllo: 'posso spiegare in 10 secondi perché?' Se sì alza, se no abbassa la confidenza. | F4: CBM≈10% Vf≈1.00 Calibrazione minima OK Obiettivo: aumentare la precisione delle motivazioni (non solo la risposta) per salire di livello. | G4: CBM≈13% Vf≈1.00 Buona calibrazione (sa e lo sa) Consolida: rivedi 2 errori e scrivi la 'regola d'oro' che li evita. | H4: CBM≈16% Vf≈1.00 Consapevolezza alta (molto ben tarato) Fai un passo in più: spiega a un compagno il criterio (insegnare = super test). | I4: CBM≈30% Vf≈1.00 Consapevolezza eccellente Sfida extra: prova a individuare i casi limite e le eccezioni (rafforza il pensiero critico).
A5: 1.5 | B5: 15 | C5: CBM≈-45% Vf≈1.50 Rischio misconcezioni / confidenza fuori bersaglio Scegli 3 risposte sbagliate e riscrivile con regola/criterio: se non trovi la regola, la prossima volta confidenza bassa. | D5: CBM≈-3% Vf≈1.50 Inconsapevolezza marcata (calibrazione scarsa) Per ogni domanda: scrivi 1 riga di motivazione. Se non la sai scrivere, confidenza bassa senza vergogna. | E5: CBM≈6% Vf≈1.50 Incertezza / calibrazione da migliorare Allenati con un controllo: 'posso spiegare in 10 secondi perché?' Se sì alza, se no abbassa la confidenza. | F5: CBM≈15% Vf≈1.50 Calibrazione minima OK Obiettivo: aumentare la precisione delle motivazioni (non solo la risposta) per salire di livello. | G5: CBM≈20% Vf≈1.50 Buona calibrazione (sa e lo sa) Consolida: rivedi 2 errori e scrivi la 'regola d'oro' che li evita. | H5: CBM≈24% Vf≈1.50 Consapevolezza alta (molto ben tarato) Fai un passo in più: spiega a un compagno il criterio (insegnare = super test). | I5: CBM≈45% Vf≈1.50 Consapevolezza eccellente Sfida extra: prova a individuare i casi limite e le eccezioni (rafforza il pensiero critico).
A6: 2 | B6: 20 | C6: CBM≈-40% Vf≈2.00 Rischio misconcezioni / confidenza fuori bersaglio Scegli 3 risposte sbagliate e riscrivile con regola/criterio: se non trovi la regola, la prossima volta confidenza bassa. | D6: CBM≈2% Vf≈2.00 Inconsapevolezza marcata (calibrazione scarsa) Per ogni domanda: scrivi 1 riga di motivazione. Se non la sai scrivere, confidenza bassa senza vergogna. | E6: CBM≈11% Vf≈2.00 Incertezza / calibrazione da migliorare Allenati con un controllo: 'posso spiegare in 10 secondi perché?' Se sì alza, se no abbassa la confidenza. | F6: CBM≈20% Vf≈2.00 Calibrazione minima OK Obiettivo: aumentare la precisione delle motivazioni (non solo la risposta) per salire di livello. | G6: CBM≈26% Vf≈2.00 Buona calibrazione (sa e lo sa) Consolida: rivedi 2 errori e scrivi la 'regola d'oro' che li evita. | H6: CBM≈32% Vf≈2.00 Consapevolezza alta (molto ben tarato) Fai un passo in più: spiega a un compagno il criterio (insegnare = super test). | I6: CBM≈60% Vf≈2.00 Consapevolezza eccellente Sfida extra: prova a individuare i casi limite e le eccezioni (rafforza il pensiero critico).
A7: 2.5 | B7: 25 | C7: CBM≈-35% Vf≈2.50 Rischio misconcezioni / confidenza fuori bersaglio Scegli 3 risposte sbagliate e riscrivile con regola/criterio: se non trovi la regola, la prossima volta confidenza bassa. | D7: CBM≈7% Vf≈2.50 Inconsapevolezza marcata (calibrazione scarsa) Per ogni domanda: scrivi 1 riga di motivazione. Se non la sai scrivere, confidenza bassa senza vergogna. | E7: CBM≈16% Vf≈2.50 Incertezza / calibrazione da migliorare Allenati con un controllo: 'posso spiegare in 10 secondi perché?' Se sì alza, se no abbassa la confidenza. | F7: CBM≈25% Vf≈2.50 Calibrazione minima OK Obiettivo: aumentare la precisione delle motivazioni (non solo la risposta) per salire di livello. | G7: CBM≈32% Vf≈2.50 Buona calibrazione (sa e lo sa) Consolida: rivedi 2 errori e scrivi la 'regola d'oro' che li evita. | H7: CBM≈40% Vf≈2.50 Consapevolezza alta (molto ben tarato) Fai un passo in più: spiega a un compagno il criterio (insegnare = super test). | I7: CBM≈75% Vf≈2.50 Consapevolezza eccellente Sfida extra: prova a individuare i casi limite e le eccezioni (rafforza il pensiero critico).
A8: 3 | B8: 30 | C8: CBM≈-30% Vf≈3.00 Rischio misconcezioni / confidenza fuori bersaglio Scegli 3 risposte sbagliate e riscrivile con regola/criterio: se non trovi la regola, la prossima volta confidenza bassa. | D8: CBM≈12% Vf≈3.00 Inconsapevolezza marcata (calibrazione scarsa) Per ogni domanda: scrivi 1 riga di motivazione. Se non la sai scrivere, confidenza bassa senza vergogna. | E8: CBM≈21% Vf≈3.00 Incertezza / calibrazione da migliorare Allenati con un controllo: 'posso spiegare in 10 secondi perché?' Se sì alza, se no abbassa la confidenza. | F8: CBM≈30% Vf≈3.00 Calibrazione minima OK Obiettivo: aumentare la precisione delle motivazioni (non solo la risposta) per salire di livello. | G8: CBM≈39% Vf≈3.00 Buona calibrazione (sa e lo sa) Consolida: rivedi 2 errori e scrivi la 'regola d'oro' che li evita. | H8: CBM≈48% Vf≈3.00 Consapevolezza alta (molto ben tarato) Fai un passo in più: spiega a un compagno il criterio (insegnare = super test). | I8: CBM≈90% Vf≈3.00 Consapevolezza eccellente Sfida extra: prova a individuare i casi limite e le eccezioni (rafforza il pensiero critico).
A9: 3.5 | B9: 35 | C9: CBM≈-25% Vf≈3.50 Rischio misconcezioni / confidenza fuori bersaglio Scegli 3 risposte sbagliate e riscrivile con regola/criterio: se non trovi la regola, la prossima volta confidenza bassa. | D9: CBM≈17% Vf≈3.50 Inconsapevolezza marcata (calibrazione scarsa) Per ogni domanda: scrivi 1 riga di motivazione. Se non la sai scrivere, confidenza bassa senza vergogna. | E9: CBM≈26% Vf≈3.50 Incertezza / calibrazione da migliorare Allenati con un controllo: 'posso spiegare in 10 secondi perché?' Se sì alza, se no abbassa la confidenza. | F9: CBM≈35% Vf≈3.50 Calibrazione minima OK Obiettivo: aumentare la precisione delle motivazioni (non solo la risposta) per salire di livello. | G9: CBM≈46% Vf≈3.50 Buona calibrazione (sa e lo sa) Consolida: rivedi 2 errori e scrivi la 'regola d'oro' che li evita. | H9: CBM≈56% Vf≈3.50 Consapevolezza alta (molto ben tarato) Fai un passo in più: spiega a un compagno il criterio (insegnare = super test). | I9: CBM≈105% Vf≈3.50 Consapevolezza eccellente Sfida extra: prova a individuare i casi limite e le eccezioni (rafforza il pensiero critico).
A10: 4 | B10: 40 | C10: CBM≈-20% Vf≈4.00 Rischio misconcezioni / confidenza fuori bersaglio Scegli 3 risposte sbagliate e riscrivile con regola/criterio: se non trovi la regola, la prossima volta confidenza bassa. | D10: CBM≈22% Vf≈4.00 Inconsapevolezza marcata (calibrazione scarsa) Per ogni domanda: scrivi 1 riga di motivazione. Se non la sai scrivere, confidenza bassa senza vergogna. | E10: CBM≈31% Vf≈4.00 Incertezza / calibrazione da migliorare Allenati con un controllo: 'posso spiegare in 10 secondi perché?' Se sì alza, se no abbassa la confidenza. | F10: CBM≈40% Vf≈4.00 Calibrazione minima OK Obiettivo: aumentare la precisione delle motivazioni (non solo la risposta) per salire di livello. | G10: CBM≈52% Vf≈4.00 Buona calibrazione (sa e lo sa) Consolida: rivedi 2 errori e scrivi la 'regola d'oro' che li evita. | H10: CBM≈64% Vf≈4.00 Consapevolezza alta (molto ben tarato) Fai un passo in più: spiega a un compagno il criterio (insegnare = super test). | I10: CBM≈120% Vf≈4.00 Consapevolezza eccellente Sfida extra: prova a individuare i casi limite e le eccezioni (rafforza il pensiero critico).
A11: 4.5 | B11: 45 | C11: CBM≈-15% Vf≈4.50 Rischio misconcezioni / confidenza fuori bersaglio Scegli 3 risposte sbagliate e riscrivile con regola/criterio: se non trovi la regola, la prossima volta confidenza bassa. | D11: CBM≈27% Vf≈4.50 Inconsapevolezza marcata (calibrazione scarsa) Per ogni domanda: scrivi 1 riga di motivazione. Se non la sai scrivere, confidenza bassa senza vergogna. | E11: CBM≈36% Vf≈4.50 Incertezza / calibrazione da migliorare Allenati con un controllo: 'posso spiegare in 10 secondi perché?' Se sì alza, se no abbassa la confidenza. | F11: CBM≈45% Vf≈4.50 Calibrazione minima OK Obiettivo: aumentare la precisione delle motivazioni (non solo la risposta) per salire di livello. | G11: CBM≈58% Vf≈4.50 Buona calibrazione (sa e lo sa) Consolida: rivedi 2 errori e scrivi la 'regola d'oro' che li evita. | H11: CBM≈72% Vf≈4.50 Consapevolezza alta (molto ben tarato) Fai un passo in più: spiega a un compagno il criterio (insegnare = super test). | I11: CBM≈135% Vf≈4.50 Consapevolezza eccellente Sfida extra: prova a individuare i casi limite e le eccezioni (rafforza il pensiero critico).
A12: 5 | B12: 50 | C12: CBM≈-10% Vf≈3.00 Rischio misconcezioni / confidenza fuori bersaglio Scegli 3 risposte sbagliate e riscrivile con regola/criterio: se non trovi la regola, la prossima volta confidenza bassa. | D12: CBM≈32% Vf≈4.05 Inconsapevolezza marcata (calibrazione scarsa) Per ogni domanda: scrivi 1 riga di motivazione. Se non la sai scrivere, confidenza bassa senza vergogna. | E12: CBM≈41% Vf≈4.28 Incertezza / calibrazione da migliorare Allenati con un controllo: 'posso spiegare in 10 secondi perché?' Se sì alza, se no abbassa la confidenza. | F12: CBM≈50% Vf≈4.50 Calibrazione minima OK Obiettivo: aumentare la precisione delle motivazioni (non solo la risposta) per salire di livello. | G12: CBM≈65% Vf≈5.03 Buona calibrazione (sa e lo sa) Consolida: rivedi 2 errori e scrivi la 'regola d'oro' che li evita. | H12: CBM≈80% Vf≈5.55 Consapevolezza alta (molto ben tarato) Fai un passo in più: spiega a un compagno il criterio (insegnare = super test). | I12: CBM≈150% Vf≈8.00 Consapevolezza eccellente Sfida extra: prova a individuare i casi limite e le eccezioni (rafforza il pensiero critico).
A13: 5.5 | B13: 55 | C13: CBM≈-5% Vf≈3.50 Rischio misconcezioni / confidenza fuori bersaglio Scegli 3 risposte sbagliate e riscrivile con regola/criterio: se non trovi la regola, la prossima volta confidenza bassa. | D13: CBM≈37% Vf≈4.55 Inconsapevolezza marcata (calibrazione scarsa) Per ogni domanda: scrivi 1 riga di motivazione. Se non la sai scrivere, confidenza bassa senza vergogna. | E13: CBM≈46% Vf≈4.78 Incertezza / calibrazione da migliorare Allenati con un controllo: 'posso spiegare in 10 secondi perché?' Se sì alza, se no abbassa la confidenza. | F13: CBM≈55% Vf≈5.00 Calibrazione minima OK Obiettivo: aumentare la precisione delle motivazioni (non solo la risposta) per salire di livello. | G13: CBM≈72% Vf≈5.53 Buona calibrazione (sa e lo sa) Consolida: rivedi 2 errori e scrivi la 'regola d'oro' che li evita. | H13: CBM≈88% Vf≈6.05 Consapevolezza alta (molto ben tarato) Fai un passo in più: spiega a un compagno il criterio (insegnare = super test). | I13: CBM≈165% Vf≈8.50 Consapevolezza eccellente Sfida extra: prova a individuare i casi limite e le eccezioni (rafforza il pensiero critico).
A14: 6 | B14: 60 | C14: CBM≈0% Vf≈4.00 Rischio misconcezioni / confidenza fuori bersaglio Scegli 3 risposte sbagliate e riscrivile con regola/criterio: se non trovi la regola, la prossima volta confidenza bassa. | D14: CBM≈42% Vf≈5.05 Inconsapevolezza marcata (calibrazione scarsa) Per ogni domanda: scrivi 1 riga di motivazione. Se non la sai scrivere, confidenza bassa senza vergogna. | E14: CBM≈51% Vf≈5.28 Incertezza / calibrazione da migliorare Allenati con un controllo: 'posso spiegare in 10 secondi perché?' Se sì alza, se no abbassa la confidenza. | F14: CBM≈60% Vf≈5.50 Calibrazione minima OK Obiettivo: aumentare la precisione delle motivazioni (non solo la risposta) per salire di livello. | G14: CBM≈78% Vf≈6.03 Buona calibrazione (sa e lo sa) Consolida: rivedi 2 errori e scrivi la 'regola d'oro' che li evita. | H14: CBM≈96% Vf≈6.55 Consapevolezza alta (molto ben tarato) Fai un passo in più: spiega a un compagno il criterio (insegnare = super test). | I14: CBM≈180% Vf≈9.00 Consapevolezza eccellente Sfida extra: prova a individuare i casi limite e le eccezioni (rafforza il pensiero critico).
A15: 6.5 | B15: 65 | C15: CBM≈5% Vf≈4.50 Rischio misconcezioni / confidenza fuori bersaglio Scegli 3 risposte sbagliate e riscrivile con regola/criterio: se non trovi la regola, la prossima volta confidenza bassa. | D15: CBM≈47% Vf≈5.55 Inconsapevolezza marcata (calibrazione scarsa) Per ogni domanda: scrivi 1 riga di motivazione. Se non la sai scrivere, confidenza bassa senza vergogna. | E15: CBM≈56% Vf≈5.78 Incertezza / calibrazione da migliorare Allenati con un controllo: 'posso spiegare in 10 secondi perché?' Se sì alza, se no abbassa la confidenza. | F15: CBM≈65% Vf≈6.00 Calibrazione minima OK Obiettivo: aumentare la precisione delle motivazioni (non solo la risposta) per salire di livello. | G15: CBM≈84% Vf≈6.53 Buona calibrazione (sa e lo sa) Consolida: rivedi 2 errori e scrivi la 'regola d'oro' che li evita. | H15: CBM≈104% Vf≈7.05 Consapevolezza alta (molto ben tarato) Fai un passo in più: spiega a un compagno il criterio (insegnare = super test). | I15: CBM≈195% Vf≈9.50 Consapevolezza eccellente Sfida extra: prova a individuare i casi limite e le eccezioni (rafforza il pensiero critico).
... A22: 10 | B22: 100 | C22: CBM≈40% Vf≈8.00 Rischio misconcezioni / confidenza fuori bersaglio Scegli 3 risposte sbagliate e riscrivile con regola/criterio: se non trovi la regola, la prossima volta confidenza bassa. | D22: CBM≈222% Vf≈9.05 Inconsapevolezza marcata (calibrazione scarsa) Per ogni domanda: scrivi 1 riga di motivazione. Se non la sai scrivere, confidenza bassa senza vergogna. | E22: CBM≈261% Vf≈9.28 Incertezza / calibrazione da migliorare Allenati con un controllo: 'posso spiegare in 10 secondi perché?' Se sì alza, se no abbassa la confidenza. | F22: CBM≈300% Vf≈10.00 Calibrazione minima OK Obiettivo: aumentare la precisione delle motivazioni (non solo la risposta) per salire di livello. | G22: CBM≈300% Vf≈10.00 Buona calibrazione (sa e lo sa) Consolida: rivedi 2 errori e scrivi la 'regola d'oro' che li evita. | H22: CBM≈300% Vf≈10.00 Consapevolezza alta (molto ben tarato) Fai un passo in più: spiega a un compagno il criterio (insegnare = super test). | I22: CBM≈300% Vf≈10.00 Consapevolezza eccellente Sfida extra: prova a individuare i casi limite e le eccezioni (rafforza il pensiero critico).

Sheet Lookup_mappa
A1: Lookup: inserisci (Voto accuracy, CBM%) → ottieni valutazione più vicina nella mappa
A3: Input | D3: Legenda livelli CBM
A4: Voto accuracy (0–10) | B4: 6 | D4: Molto sotto (y_low)
A5: CBM% | B5: 120 | D5: Sotto 2
A6: Accuracy% (calcolato) | B6: =B4*10 | D6: Sotto 1
D7: Sulla spezzata (y_min)
A8: Risultato (punto più vicino) | D8: Sopra 1
A9: Distanza^2 minima | B9: =MIN($S$25:$S$45) | D9: Sopra 2
A10: Indice candidato (1=V-,2=V0,3=V+) | B10: =INT((MATCH($B$9,$S$25:$S$45,0)-1)/7)+1 | D10: Retta consapevolezza (y_max)
A11: LevelID (1..7) | B11: =MOD(MATCH($B$9,$S$25:$S$45,0)-1,7)+1
A12: V_acc mappato | B12: =CHOOSE($B$10,$E$20,$E$21,$E$22)
A13: CBM% mappato | B13: =INDEX($F$20:$L$22,$B$10,$B$11)
A14: Voto finale stimato | B14: =VLOOKUP($B$18,Data_mappa!$O$2:$S$134,2,FALSE)
A15: Profilo | B15: =VLOOKUP($B$18,Data_mappa!$O$2:$S$134,3,FALSE)
A16: Feedback (breve) | B16: =VLOOKUP($B$18,Data_mappa!$O$2:$S$134,4,FALSE)
A17: Feedback (esteso) | B17: =VLOOKUP($B$18,Data_mappa!$O$2:$S$134,5,FALSE)
A18: Key | B18: =TEXT($B$12,"0.0")&"|"&$B$19
A19: Livello (da indice) | B19: =CHOOSE($B$11,"Molto sotto (y_low)","Sotto 2","Sotto 1","Sulla spezzata (y_min)","Sopra 1","Sopra 2","Retta consapevolezza (y_max)") | E19: V_acc candidati | F19: Molto sotto (y_low) | G19: Sotto 2 | H19: Sotto 1 | I19: Sulla spezzata (y_min) | J19: Sopra 1 | K19: Sopra 2 | L19: Retta consapevolezza (y_max)
A20: V- | E20: =MAX(1,ROUND($B$4/0.5,0)*0.5-0.5) | F20: =P20 | G20: =N20-Parametri_mappa!$E$5*Q20 | H20: =N20-Parametri_mappa!$E$4*Q20 | I20: =N20 | J20: =N20+Parametri_mappa!$E$4*R20 | K20: =N20+Parametri_mappa!$E$5*R20 | L20: =O20 | M20: =$E20*10 | N20: =IF(M20<=66.6,M20,IF(M20<=80,4*M20-200,9*M20-600)) | O20: =3*M20 | P20: =M20-60 | Q20: =N20-P20 | R20: =O20-N20
A21: V0 | E21: =ROUND($B$4/0.5,0)*0.5 | F21: =P21 | G21: =N21-Parametri_mappa!$E$5*Q21 | H21: =N21-Parametri_mappa!$E$4*Q21 | I21: =N21 | J21: =N21+Parametri_mappa!$E$4*R21 | K21: =N21+Parametri_mappa!$E$5*R21 | L21: =O21 | M21: =$E21*10 | N21: =IF(M21<=66.6,M21,IF(M21<=80,4*M21-200,9*M21-600)) | O21: =3*M21 | P21: =M21-60 | Q21: =N21-P21 | R21: =O21-N21
A22: V+ | E22: =MIN(10,ROUND($B$4/0.5,0)*0.5+0.5) | F22: =P22 | G22: =N22-Parametri_mappa!$E$5*Q22 | H22: =N22-Parametri_mappa!$E$4*Q22 | I22: =N22 | J22: =N22+Parametri_mappa!$E$4*R22 | K22: =N22+Parametri_mappa!$E$5*R22 | L22: =O22 | M22: =$E22*10 | N22: =IF(M22<=66.6,M22,IF(M22<=80,4*M22-200,9*M22-600)) | O22: =3*M22 | P22: =M22-60 | Q22: =N22-P22 | R22: =O22-N22
E24: dist2 (vs input) | S24: flat
F25: =(( $E20-$B$4)/Parametri_mappa!$E$8)^2+((F20-$B$5)/Parametri_mappa!$E$9)^2 | G25: =(( $E20-$B$4)/Parametri_mappa!$E$8)^2+((G20-$B$5)/Parametri_mappa!$E$9)^2 | H25: =(( $E20-$B$4)/Parametri_mappa!$E$8)^2+((H20-$B$5)/Parametri_mappa!$E$9)^2 | I25: =(( $E20-$B$4)/Parametri_mappa!$E$8)^2+((I20-$B$5)/Parametri_mappa!$E$9)^2 | J25: =(( $E20-$B$4)/Parametri_mappa!$E$8)^2+((J20-$B$5)/Parametri_mappa!$E$9)^2 | K25: =(( $E20-$B$4)/Parametri_mappa!$E$8)^2+((K20-$B$5)/Parametri_mappa!$E$9)^2 | L25: =(( $E20-$B$4)/Parametri_mappa!$E$8)^2+((L20-$B$5)/Parametri_mappa!$E$9)^2 | S25: =F25
F26: =(( $E21-$B$4)/Parametri_mappa!$E$8)^2+((F21-$B$5)/Parametri_mappa!$E$9)^2 | G26: =(( $E21-$B$4)/Parametri_mappa!$E$8)^2+((G21-$B$5)/Parametri_mappa!$E$9)^2 | H26: =(( $E21-$B$4)/Parametri_mappa!$E$8)^2+((H21-$B$5)/Parametri_mappa!$E$9)^2 | I26: =(( $E21-$B$4)/Parametri_mappa!$E$8)^2+((I21-$B$5)/Parametri_mappa!$E$9)^2 | J26: =(( $E21-$B$4)/Parametri_mappa!$E$8)^2+((J21-$B$5)/Parametri_mappa!$E$9)^2 | K26: =(( $E21-$B$4)/Parametri_mappa!$E$8)^2+((K21-$B$5)/Parametri_mappa!$E$9)^2 | L26: =(( $E21-$B$4)/Parametri_mappa!$E$8)^2+((L21-$B$5)/Parametri_mappa!$E$9)^2 | S26: =G25
F27: =(( $E22-$B$4)/Parametri_mappa!$E$8)^2+((F22-$B$5)/Parametri_mappa!$E$9)^2 | G27: =(( $E22-$B$4)/Parametri_mappa!$E$8)^2+((G22-$B$5)/Parametri_mappa!$E$9)^2 | H27: =(( $E22-$B$4)/Parametri_mappa!$E$8)^2+((H22-$B$5)/Parametri_mappa!$E$9)^2 | I27: =(( $E22-$B$4)/Parametri_mappa!$E$8)^2+((I22-$B$5)/Parametri_mappa!$E$9)^2 | J27: =(( $E22-$B$4)/Parametri_mappa!$E$8)^2+((J22-$B$5)/Parametri_mappa!$E$9)^2 | K27: =(( $E22-$B$4)/Parametri_mappa!$E$8)^2+((K22-$B$5)/Parametri_mappa!$E$9)^2 | L27: =(( $E22-$B$4)/Parametri_mappa!$E$8)^2+((L22-$B$5)/Parametri_mappa!$E$9)^2 | S27: =H25
S28: =I25
S29: =J25
S30: =K25
S31: =L25
S32: =F26
S33: =G26
S34: =H26
S35: =I26
S36: =J26
S37: =K26
S38: =L26
S39: =F27
S40: =G27
S41: =H27
S42: =I27
...

Sheet CBM
A1: CBM (Certainty-Based Marking) – 10 scenari su test da 5 domande
A2: Legenda: Risposta=1 corretta, 0 sbagliata. Certezza: L=bassa, M=media, H=alta. Punteggi CBM e voti sono calcolati con formule (modificabili dai parametri sotto).
A4: Parametri CBM (modifica qui) | F4: Conversione in voto (0–10) | L4: Mini-dashboard (automatico)
A5: Certezza | B5: Valore | C5: Punti se corretta | D5: Punti se sbagliata | F5: CBM minimo | G5: -30 | L5: Media voto accuratezza | M5: =AVERAGE(S12:S21) | R5: Punti max di malus | S5: 2 | V5: Parametri della spezzata | W5: soglia1-2 | X5: 66.6 | AA5: x spezzata | AB5: 0 | AC5: 0.2 | AD5: 0.4 | AE5: 0.6 | AF5: 0.8 | AG5: 1 | AH5: 1.2 | AI5: 1.4 | AJ5: 1.6 | AK5: 1.8 | AL5: 2 | AM5: 2.2 | AN5: 2.4 | AO5: 2.6 | AP5: 2.8 | AQ5: 3 | AR5: 3.2 | AS5: 3.4 | AT5: 3.6 | AU5: 3.8 | AV5: 4 | AW5: 4.2 | AX5: 4.4 | AY5: 4.6 | AZ5: 4.8 | BA5: 5 | BB5: 5.2 | BC5: 5.4 | BD5: 5.6 | BE5: 5.8 | BF5: 6 | BG5: 6.2 | BH5: 6.4 | BI5: 6.6 | BJ5: 6.8 | BK5: 7 | BL5: 7.2 | BM5: 7.4 | BN5: 7.6 | BO5: 7.8 | BP5: 8 | BQ5: 8.2 | BR5: 8.4 | BS5: 8.6 | BT5: 8.8 | BU5: 9 | BV5: 9.2 | BW5: 9.4 | BX5: 9.6 | BY5: 9.8 | BZ5: 10
A6: L (bassa) | B6: L | C6: 1 | D6: 0 | F6: CBM massimo | G6: 15 | L6: Media voto CBM | M6: =AVERAGE(U12:U21) | R6: Punti max di bonus | S6: 1 | W6: soglia2-3 | X6: 80 | AA6: y spezzata | AB6: =IF(AB5<=$X$5/10,AB5*$X$7+$Y$7,IF(AB5<=$X$6/10,$X$8*AB5+$Y$8/10,$X$9*AB5+$Y$9/10)) | AC6: =IF(AC5<=$X$5/10,AC5*$X$7+$Y$7,IF(AC5<=$X$6/10,$X$8*AC5+$Y$8/10,$X$9*AC5+$Y$9/10)) | AD6: =IF(AD5<=$X$5/10,AD5*$X$7+$Y$7,IF(AD5<=$X$6/10,$X$8*AD5+$Y$8/10,$X$9*AD5+$Y$9/10)) | AE6: =IF(AE5<=$X$5/10,AE5*$X$7+$Y$7,IF(AE5<=$X$6/10,$X$8*AE5+$Y$8/10,$X$9*AE5+$Y$9/10)) | AF6: =IF(AF5<=$X$5/10,AF5*$X$7+$Y$7,IF(AF5<=$X$6/10,$X$8*AF5+$Y$8/10,$X$9*AF5+$Y$9/10)) | AG6: =IF(AG5<=$X$5/10,AG5*$X$7+$Y$7,IF(AG5<=$X$6/10,$X$8*AG5+$Y$8/10,$X$9*AG5+$Y$9/10)) | AH6: =IF(AH5<=$X$5/10,AH5*$X$7+$Y$7,IF(AH5<=$X$6/10,$X$8*AH5+$Y$8/10,$X$9*AH5+$Y$9/10)) | AI6: =IF(AI5<=$X$5/10,AI5*$X$7+$Y$7,IF(AI5<=$X$6/10,$X$8*AI5+$Y$8/10,$X$9*AI5+$Y$9/10)) | ... BZ6: =IF(BZ5<=$X$5/10,BZ5*$X$7+$Y$7,IF(BZ5<=$X$6/10,$X$8*BZ5+$Y$8/10,$X$9*BZ5+$Y$9/10))
A7: M (media) | B7: M | C7: 2 | D7: -2 | F7: Peso CBM (0–1) | G7: 0.5 | L7: Media voto finale | M7: =AVERAGE(AB12:AB21) | R7: Punti sulla spezzata | S7: -0.5 | W7: spezzata1 m,q | X7: 1 | Y7: 0
A8: H (alta) | B8: H | C8: 3 | D8: -6 | F8: Peso Accuratezza (auto) | G8: =1-G7 | W8: spezzata2 m,q | X8: 4 | Y8: =X7*X5+Y7-X8*X5
W9: spezzata3 m,q | X9: 9 | Y9: =X8*X6+Y8-X9*X6
A11: Scenario | B11: Q1 Risposta | C11: Q1 Certezza | D11: Q1 Punti CBM | E11: Q2 Risposta | F11: Q2 Certezza | G11: Q2 Punti CBM | H11: Q3 Risposta | I11: Q3 Certezza | J11: Q3 Punti CBM | K11: Q4 Risposta | L11: Q4 Certezza | M11: Q4 Punti CBM | N11: Q5 Risposta | O11: Q5 Certezza | P11: Q5 Punti CBM | Q11: Tot. corrette | R11: Accuratezza % | S11: Voto accuratezza (0-10) | T11: Punti CBM (assoluti) | U11: Voto CBM (0-10) | V11: Accuratezza (0-100) | W11: CBM (0-100) | X11: Spezzata comprensione minima y_min (0-100) | Y11: Retta comprensione y=3x (0-100) | Z11: =CONCAT("adj (",-(10*S5)," …+",10*S6,")") | AA11: Voto finale (regola spezzata) | AB11: Voto finale (1-10)
A12: Scenario 1 | B12: 1 | C12: H | D12: =IF(B12=1, VLOOKUP(C12,$B$6:$D$8,2,FALSE), VLOOKUP(C12,$B$6:$D$8,3,FALSE)) | E12: 1 | F12: H | G12: =IF(E12=1, VLOOKUP(F12,$B$6:$D$8,2,FALSE), VLOOKUP(F12,$B$6:$D$8,3,FALSE)) | H12: 1 | I12: H | J12: =IF(H12=1, VLOOKUP(I12,$B$6:$D$8,2,FALSE), VLOOKUP(I12,$B$6:$D$8,3,FALSE)) | K12: 0 | L12: L | M12: =IF(K12=1, VLOOKUP(L12,$B$6:$D$8,2,FALSE), VLOOKUP(L12,$B$6:$D$8,3,FALSE)) | N12: 0 | O12: L | P12: =IF(N12=1, VLOOKUP(O12,$B$6:$D$8,2,FALSE), VLOOKUP(O12,$B$6:$D$8,3,FALSE)) | Q12: =SUM(B12,E12,H12,K12,N12) | R12: =Q12/5 | S12: =R12*10 | T12: =SUM(D12,G12,J12,M12,P12) | U12: =T12*2 | V12: =R12*100 | W12: =U12*10 | X12: =IF(V12<=$X$5,V12*$X$7+$Y$7,IF(V12<=$X$6,$X$8*V12+$Y$8,$X$9*V12+$Y$9)) | Y12: =3*V12 | Z12: =IF(V12<50,0,IF(W12=300,0,IF(W12>=X12,$S$7 + (-$S$7+$S$6)*(W12-X12)/MAX(0.0001,(Y12-X12)),IF(W12<=(V12-60),-$S$5,$S$7 - ($S$5+$S$7)*(X12-W12)/MAX(0.0001,(X12-(V12-60)))))))*10 | AA12: =MAX(10,MIN(100, IF(V12<50,V12,V12+Z12))) | AB12: =AA12/10
A13: Scenario 2 | B13: 1 | C13: M | D13: =IF(B13=1, VLOOKUP(C13,$B$6:$D$8,2,FALSE), VLOOKUP(C13,$B$6:$D$8,3,FALSE)) | E13: 1 | F13: M | G13: =IF(E13=1, VLOOKUP(F13,$B$6:$D$8,2,FALSE), VLOOKUP(F13,$B$6:$D$8,3,FALSE)) | H13: 1 | I13: M | J13: =IF(H13=1, VLOOKUP(I13,$B$6:$D$8,2,FALSE), VLOOKUP(I13,$B$6:$D$8,3,FALSE)) | K13: 1 | L13: M | M13: =IF(K13=1, VLOOKUP(L13,$B$6:$D$8,2,FALSE), VLOOKUP(L13,$B$6:$D$8,3,FALSE)) | N13: 1 | O13: M | P13: =IF(N13=1, VLOOKUP(O13,$B$6:$D$8,2,FALSE), VLOOKUP(O13,$B$6:$D$8,3,FALSE)) | Q13: =SUM(B13,E13,H13,K13,N13) | R13: =Q13/5 | S13: =R13*10 | T13: =SUM(D13,G13,J13,M13,P13) | U13: =T13*2 | V13: =R13*100 | W13: =U13*10 | X13: =IF(V13<=$X$5,V13*$X$7+$Y$7,IF(V13<=$X$6,$X$8*V13+$Y$8,$X$9*V13+$Y$9)) | Y13: =3*V13 | Z13: =IF(V13<50,0,IF(W13=300,0,IF(W13>=X13,$S$7 + (-$S$7+$S$6)*(W13-X13)/MAX(0.0001,(Y13-X13)),IF(W13<=(V13-60),-$S$5,$S$7 - ($S$5+$S$7)*(X13-W13)/MAX(0.0001,(X13-(V13-60)))))))*10 | AA13: =MAX(10,MIN(100, IF(V13<50,V13,V13+Z13))) | AB13: =AA13/10
A14: Scenario 3 | B14: 1 | C14: H | D14: =IF(B14=1, VLOOKUP(C14,$B$6:$D$8,2,FALSE), VLOOKUP(C14,$B$6:$D$8,3,FALSE)) | E14: 1 | F14: H | G14: =IF(E14=1, VLOOKUP(F14,$B$6:$D$8,2,FALSE), VLOOKUP(F14,$B$6:$D$8,3,FALSE)) | H14: 0 | I14: H | J14: =IF(H14=1, VLOOKUP(I14,$B$6:$D$8,2,FALSE), VLOOKUP(I14,$B$6:$D$8,3,FALSE)) | K14: 0 | L14: H | M14: =IF(K14=1, VLOOKUP(L14,$B$6:$D$8,2,FALSE), VLOOKUP(L14,$B$6:$D$8,3,FALSE)) | N14: 0 | O14: H | P14: =IF(N14=1, VLOOKUP(O14,$B$6:$D$8,2,FALSE), VLOOKUP(O14,$B$6:$D$8,3,FALSE)) | Q14: =SUM(B14,E14,H14,K14,N14) | R14: =Q14/5 | S14: =R14*10 | T14: =SUM(D14,G14,J14,M14,P14) | U14: =T14*2 | V14: =R14*100 | W14: =U14*10 | X14: =IF(V14<=$X$5,V14*$X$7+$Y$7,IF(V14<=$X$6,$X$8*V14+$Y$8,$X$9*V14+$Y$9)) | Y14: =3*V14 | Z14: =IF(V14<50,0,IF(W14=300,0,IF(W14>=X14,$S$7 + (-$S$7+$S$6)*(W14-X14)/MAX(0.0001,(Y14-X14)),IF(W14<=(V14-60),-$S$5,$S$7 - ($S$5+$S$7)*(X14-W14)/MAX(0.0001,(X14-(V14-60)))))))*10 | AA14: =MAX(10,MIN(100, IF(V14<50,V14,V14+Z14))) | AB14: =AA14/10
A15: Scenario 4 | B15: 1 | C15: L | D15: =IF(B15=1, VLOOKUP(C15,$B$6:$D$8,2,FALSE), VLOOKUP(C15,$B$6:$D$8,3,FALSE)) | E15: 1 | F15: L | G15: =IF(E15=1, VLOOKUP(F15,$B$6:$D$8,2,FALSE), VLOOKUP(F15,$B$6:$D$8,3,FALSE)) | H15: 1 | I15: L | J15: =IF(H15=1, VLOOKUP(I15,$B$6:$D$8,2,FALSE), VLOOKUP(I15,$B$6:$D$8,3,FALSE)) | K15: 0 | L15: L | M15: =IF(K15=1, VLOOKUP(L15,$B$6:$D$8,2,FALSE), VLOOKUP(L15,$B$6:$D$8,3,FALSE)) | N15: 0 | O15: L | P15: =IF(N15=1, VLOOKUP(O15,$B$6:$D$8,2,FALSE), VLOOKUP(O15,$B$6:$D$8,3,FALSE)) | Q15: =SUM(B15,E15,H15,K15,N15) | R15: =Q15/5 | S15: =R15*10 | T15: =SUM(D15,G15,J15,M15,P15) | U15: =T15*2 | V15: =R15*100 | W15: =U15*10 | X15: =IF(V15<=$X$5,V15*$X$7+$Y$7,IF(V15<=$X$6,$X$8*V15+$Y$8,$X$9*V15+$Y$9)) | Y15: =3*V15 | Z15: =IF(V15<50,0,IF(W15=300,0,IF(W15>=X15,$S$7 + (-$S$7+$S$6)*(W15-X15)/MAX(0.0001,(Y15-X15)),IF(W15<=(V15-60),-$S$5,$S$7 - ($S$5+$S$7)*(X15-W15)/MAX(0.0001,(X15-(V15-60)))))))*10 | AA15: =MAX(10,MIN(100, IF(V15<50,V15,V15+Z15))) | AB15: =AA15/10
A16: Scenario 5 | B16: 1 | C16: H | D16: =IF(B16=1, VLOOKUP(C16,$B$6:$D$8,2,FALSE), VLOOKUP(C16,$B$6:$D$8,3,FALSE)) | E16: 1 | F16: H | G16: =IF(E16=1, VLOOKUP(F16,$B$6:$D$8,2,FALSE), VLOOKUP(F16,$B$6:$D$8,3,FALSE)) | H16: 1 | I16: H | J16: =IF(H16=1, VLOOKUP(I16,$B$6:$D$8,2,FALSE), VLOOKUP(I16,$B$6:$D$8,3,FALSE)) | K16: 1 | L16: H | M16: =IF(K16=1, VLOOKUP(L16,$B$6:$D$8,2,FALSE), VLOOKUP(L16,$B$6:$D$8,3,FALSE)) | N16: 0 | O16: H | P16: =IF(N16=1, VLOOKUP(O16,$B$6:$D$8,2,FALSE), VLOOKUP(O16,$B$6:$D$8,3,FALSE)) | Q16: =SUM(B16,E16,H16,K16,N16) | R16: =Q16/5 | S16: =R16*10 | T16: =SUM(D16,G16,J16,M16,P16) | U16: =T16*2 | V16: =R16*100 | W16: =U16*10 | X16: =IF(V16<=$X$5,V16*$X$7+$Y$7,IF(V16<=$X$6,$X$8*V16+$Y$8,$X$9*V16+$Y$9)) | Y16: =3*V16 | Z16: =IF(V16<50,0,IF(W16=300,0,IF(W16>=X16,$S$7 + (-$S$7+$S$6)*(W16-X16)/MAX(0.0001,(Y16-X16)),IF(W16<=(V16-60),-$S$5,$S$7 - ($S$5+$S$7)*(X16-W16)/MAX(0.0001,(X16-(V16-60)))))))*10 | AA16: =MAX(10,MIN(100, IF(V16<50,V16,V16+Z16))) | AB16: =AA16/10
A17: Scenario 6 | B17: 1 | C17: M | D17: =IF(B17=1, VLOOKUP(C17,$B$6:$D$8,2,FALSE), VLOOKUP(C17,$B$6:$D$8,3,FALSE)) | E17: 1 | F17: M | G17: =IF(E17=1, VLOOKUP(F17,$B$6:$D$8,2,FALSE), VLOOKUP(F17,$B$6:$D$8,3,FALSE)) | H17: 1 | I17: M | J17: =IF(H17=1, VLOOKUP(I17,$B$6:$D$8,2,FALSE), VLOOKUP(I17,$B$6:$D$8,3,FALSE)) | K17: 0 | L17: M | M17: =IF(K17=1, VLOOKUP(L17,$B$6:$D$8,2,FALSE), VLOOKUP(L17,$B$6:$D$8,3,FALSE)) | N17: 0 | O17: M | P17: =IF(N17=1, VLOOKUP(O17,$B$6:$D$8,2,FALSE), VLOOKUP(O17,$B$6:$D$8,3,FALSE)) | Q17: =SUM(B17,E17,H17,K17,N17) | R17: =Q17/5 | S17: =R17*10 | T17: =SUM(D17,G17,J17,M17,P17) | U17: =T17*2 | V17: =R17*100 | W17: =U17*10 | X17: =IF(V17<=$X$5,V17*$X$7+$Y$7,IF(V17<=$X$6,$X$8*V17+$Y$8,$X$9*V17+$Y$9)) | Y17: =3*V17 | Z17: =IF(V17<50,0,IF(W17=300,0,IF(W17>=X17,$S$7 + (-$S$7+$S$6)*(W17-X17)/MAX(0.0001,(Y17-X17)),IF(W17<=(V17-60),-$S$5,$S$7 - ($S$5+$S$7)*(X17-W17)/MAX(0.0001,(X17-(V17-60)))))))*10 | AA17: =MAX(10,MIN(100, IF(V17<50,V17,V17+Z17))) | AB17: =AA17/10
A18: Scenario 7 | B18: 1 | C18: H | D18: =IF(B18=1, VLOOKUP(C18,$B$6:$D$8,2,FALSE), VLOOKUP(C18,$B$6:$D$8,3,FALSE)) | E18: 0 | F18: L | G18: =IF(E18=1, VLOOKUP(F18,$B$6:$D$8,2,FALSE), VLOOKUP(F18,$B$6:$D$8,3,FALSE)) | H18: 0 | I18: L | J18: =IF(H18=1, VLOOKUP(I18,$B$6:$D$8,2,FALSE), VLOOKUP(I18,$B$6:$D$8,3,FALSE)) | K18: 0 | L18: L | M18: =IF(K18=1, VLOOKUP(L18,$B$6:$D$8,2,FALSE), VLOOKUP(L18,$B$6:$D$8,3,FALSE)) | N18: 0 | O18: L | P18: =IF(N18=1, VLOOKUP(O18,$B$6:$D$8,2,FALSE), VLOOKUP(O18,$B$6:$D$8,3,FALSE)) | Q18: =SUM(B18,E18,H18,K18,N18) | R18: =Q18/5 | S18: =R18*10 | T18: =SUM(D18,G18,J18,M18,P18) | U18: =T18*2 | V18: =R18*100 | W18: =U18*10 | X18: =IF(V18<=$X$5,V18*$X$7+$Y$7,IF(V18<=$X$6,$X$8*V18+$Y$8,$X$9*V18+$Y$9)) | Y18: =3*V18 | Z18: =IF(V18<50,0,IF(W18=300,0,IF(W18>=X18,$S$7 + (-$S$7+$S$6)*(W18-X18)/MAX(0.0001,(Y18-X18)),IF(W18<=(V18-60),-$S$5,$S$7 - ($S$5+$S$7)*(X18-W18)/MAX(0.0001,(X18-(V18-60)))))))*10 | AA18: =MAX(10,MIN(100, IF(V18<50,V18,V18+Z18))) | AB18: =AA18/10
A19: Scenario 8 | B19: 0 | C19: L | D19: =IF(B19=1, VLOOKUP(C19,$B$6:$D$8,2,FALSE), VLOOKUP(C19,$B$6:$D$8,3,FALSE)) | E19: 0 | F19: M | G19: =IF(E19=1, VLOOKUP(F19,$B$6:$D$8,2,FALSE), VLOOKUP(F19,$B$6:$D$8,3,FALSE)) | H19: 1 | I19: H | J19: =IF(H19=1, VLOOKUP(I19,$B$6:$D$8,2,FALSE), VLOOKUP(I19,$B$6:$D$8,3,FALSE)) | K19: 1 | L19: M | M19: =IF(K19=1, VLOOKUP(L19,$B$6:$D$8,2,FALSE), VLOOKUP(L19,$B$6:$D$8,3,FALSE)) | N19: 1 | O19: H | P19: =IF(N19=1, VLOOKUP(O19,$B$6:$D$8,2,FALSE), VLOOKUP(O19,$B$6:$D$8,3,FALSE)) | Q19: =SUM(B19,E19,H19,K19,N19) | R19: =Q19/5 | S19: =R19*10 | T19: =SUM(D19,G19,J19,M19,P19) | U19: =T19*2 | V19: =R19*100 | W19: =U19*10 | X19: =IF(V19<=$X$5,V19*$X$7+$Y$7,IF(V19<=$X$6,$X$8*V19+$Y$8,$X$9*V19+$Y$9)) | Y19: =3*V19 | Z19: =IF(V19<50,0,IF(W19=300,0,IF(W19>=X19,$S$7 + (-$S$7+$S$6)*(W19-X19)/MAX(0.0001,(Y19-X19)),IF(W19<=(V19-60),-$S$5,$S$7 - ($S$5+$S$7)*(X19-W19)/MAX(0.0001,(X19-(V19-60)))))))*10 | AA19: =MAX(10,MIN(100, IF(V19<50,V19,V19+Z19))) | AB19: =AA19/10
A20: Scenario 9 | B20: 1 | C20: M | D20: =IF(B20=1, VLOOKUP(C20,$B$6:$D$8,2,FALSE), VLOOKUP(C20,$B$6:$D$8,3,FALSE)) | E20: 1 | F20: H | G20: =IF(E20=1, VLOOKUP(F20,$B$6:$D$8,2,FALSE), VLOOKUP(F20,$B$6:$D$8,3,FALSE)) | H20: 1 | I20: H | J20: =IF(H20=1, VLOOKUP(I20,$B$6:$D$8,2,FALSE), VLOOKUP(I20,$B$6:$D$8,3,FALSE)) | K20: 1 | L20: H | M20: =IF(K20=1, VLOOKUP(L20,$B$6:$D$8,2,FALSE), VLOOKUP(L20,$B$6:$D$8,3,FALSE)) | N20: 1 | O20: H | P20: =IF(N20=1, VLOOKUP(O20,$B$6:$D$8,2,FALSE), VLOOKUP(O20,$B$6:$D$8,3,FALSE)) | Q20: =SUM(B20,E20,H20,K20,N20) | R20: =Q20/5 | S20: =R20*10 | T20: =SUM(D20,G20,J20,M20,P20) | U20: =T20*2 | V20: =R20*100 | W20: =U20*10 | X20: =IF(V20<=$X$5,V20*$X$7+$Y$7,IF(V20<=$X$6,$X$8*V20+$Y$8,$X$9*V20+$Y$9)) | Y20: =3*V20 | Z20: =IF(V20<50,0,IF(W20=300,0,IF(W20>=X20,$S$7 + (-$S$7+$S$6)*(W20-X20)/MAX(0.0001,(Y20-X20)),IF(W20<=(V20-60),-$S$5,$S$7 - ($S$5+$S$7)*(X20-W20)/MAX(0.0001,(X20-(V20-60)))))))*10 | AA20: =MAX(10,MIN(100, IF(V20<50,V20,V20+Z20))) | AB20: =AA20/10
A21: Scenario10 | B21: 1 | C21: H | D21: =IF(B21=1, VLOOKUP(C21,$B$6:$D$8,2,FALSE), VLOOKUP(C21,$B$6:$D$8,3,FALSE)) | E21: 1 | F21: H | G21: =IF(E21=1, VLOOKUP(F21,$B$6:$D$8,2,FALSE), VLOOKUP(F21,$B$6:$D$8,3,FALSE)) | H21: 1 | I21: H | J21: =IF(H21=1, VLOOKUP(I21,$B$6:$D$8,2,FALSE), VLOOKUP(I21,$B$6:$D$8,3,FALSE)) | K21: 0 | L21: H | M21: =IF(K21=1, VLOOKUP(L21,$B$6:$D$8,2,FALSE), VLOOKUP(L21,$B$6:$D$8,3,FALSE)) | N21: 0 | O21: H | P21: =IF(N21=1, VLOOKUP(O21,$B$6:$D$8,2,FALSE), VLOOKUP(O21,$B$6:$D$8,3,FALSE)) | Q21: =SUM(B21,E21,H21,K21,N21) | R21: =Q21/5 | S21: =R21*10 | T21: =SUM(D21,G21,J21,M21,P21) | U21: =T21*2 | V21: =R21*100 | W21: =U21*10 | X21: =IF(V21<=$X$5,V21*$X$7+$Y$7,IF(V21<=$X$6,$X$8*V21+$Y$8,$X$9*V21+$Y$9)) | Y21: =3*V21 | Z21: =IF(V21<50,0,IF(W21=300,0,IF(W21>=X21,$S$7 + (-$S$7+$S$6)*(W21-X21)/MAX(0.0001,(Y21-X21)),IF(W21<=(V21-60),-$S$5,$S$7 - ($S$5+$S$7)*(X21-W21)/MAX(0.0001,(X21-(V21-60)))))))*10 | AA21: =MAX(10,MIN(100, IF(V21<50,V21,V21+Z21))) | AB21: =AA21/10
